Workbook

Sheet Блюда
A1: № | B1: Категория | C1: Название | D1: Станция | E1: Вес порции (г) ↻ | F1: Себест. порции (TJS) ↻ | G1: Цена продажи (TJS) | H1: Food Cost % | I1: Наценка % | J1: Кол-во ингр. ↻ | K1: Время (мин) | L1: Доступно
A2: 1 | B2: Салаты | C2: Салат Каприз | D2: cold_kitchen | E2: =SUMIF(Техкарты!A:A,C2,Техкарты!D:D) | F2: =SUMIF(Техкарты!A:A,C2,Техкарты!G:G) | G2: 22 | H2: =IF(G2>0,F2/G2*100,0) | I2: =IF(F2>0,(G2-F2)/F2*100,0) | J2: =COUNTIF(Техкарты!A:A,C2) | L2: Да
A3: 2 | B3: Супы | C3: Мастова | D3: hot_kitchen | E3: =SUMIF(Техкарты!A:A,C3,Техкарты!D:D) | F3: =SUMIF(Техкарты!A:A,C3,Техкарты!G:G) | G3: 12 | H3: =IF(G3>0,F3/G3*100,0) | I3: =IF(F3>0,(G3-F3)/F3*100,0) | J3: =COUNTIF(Техкарты!A:A,C3) | L3: Да
A4: 3 | B4: Супы | C4: Реза Шурбо | D4: hot_kitchen | E4: =SUMIF(Техкарты!A:A,C4,Техкарты!D:D) | F4: =SUMIF(Техкарты!A:A,C4,Техкарты!G:G) | G4: 16 | H4: =IF(G4>0,F4/G4*100,0) | I4: =IF(F4>0,(G4-F4)/F4*100,0) | J4: =COUNTIF(Техкарты!A:A,C4) | L4: Да
A5: 4 | B5: Супы | C5: Лагман | D5: hot_kitchen | E5: =SUMIF(Техкарты!A:A,C5,Техкарты!D:D) | F5: =SUMIF(Техкарты!A:A,C5,Техкарты!G:G) | G5: 25 | H5: =IF(G5>0,F5/G5*100,0) | I5: =IF(F5>0,(G5-F5)/F5*100,0) | J5: =COUNTIF(Техкарты!A:A,C5) | L5: Да
A6: 5 | B6: Супы | C6: Хом Шурво | D6: hot_kitchen | E6: =SUMIF(Техкарты!A:A,C6,Техкарты!D:D) | F6: =SUMIF(Техкарты!A:A,C6,Техкарты!G:G) | G6: 20 | H6: =IF(G6>0,F6/G6*100,0) | I6: =IF(F6>0,(G6-F6)/F6*100,0) | J6: =COUNTIF(Техкарты!A:A,C6) | L6: Да
A7: 6 | B7: Супы | C7: 3В1 | D7: hot_kitchen | E7: =SUMIF(Техкарты!A:A,C7,Техкарты!D:D) | F7: =SUMIF(Техкарты!A:A,C7,Техкарты!G:G) | H7: =IF(G7>0,F7/G7*100,0) | I7: =IF(F7>0,(G7-F7)/F7*100,0) | J7: =COUNTIF(Техкарты!A:A,C7) | L7: Да
A8: 7 | B8: Супы | C8: Жавари | D8: hot_kitchen | E8: =SUMIF(Техкарты!A:A,C8,Техкарты!D:D) | F8: =SUMIF(Техкарты!A:A,C8,Техкарты!G:G) | G8: 14 | H8: =IF(G8>0,F8/G8*100,0) | I8: =IF(F8>0,(G8-F8)/F8*100,0) | J8: =COUNTIF(Техкарты!A:A,C8) | L8: Да
A9: 8 | B9: Супы | C9: Мастова Домашный | D9: hot_kitchen | E9: =SUMIF(Техкарты!A:A,C9,Техкарты!D:D) | F9: =SUMIF(Техкарты!A:A,C9,Техкарты!G:G) | G9: 14 | H9: =IF(G9>0,F9/G9*100,0) | I9: =IF(F9>0,(G9-F9)/F9*100,0) | J9: =COUNTIF(Техкарты!A:A,C9) | L9: Да
A10: 9 | B10: Супы | C10: Чучвара | D10: hot_kitchen | E10: =SUMIF(Техкарты!A:A,C10,Техкарты!D:D) | F10: =SUMIF(Техкарты!A:A,C10,Техкарты!G:G) | G10: 18 | H10: =IF(G10>0,F10/G10*100,0) | I10: =IF(F10>0,(G10-F10)/F10*100,0) | J10: =COUNTIF(Техкарты!A:A,C10) | L10: Да
A11: 10 | B11: Супы | C11: Угро | D11: hot_kitchen | E11: =SUMIF(Техкарты!A:A,C11,Техкарты!D:D) | F11: =SUMIF(Техкарты!A:A,C11,Техкарты!G:G) | G11: 16 | H11: =IF(G11>0,F11/G11*100,0) | I11: =IF(F11>0,(G11-F11)/F11*100,0) | J11: =COUNTIF(Техкарты!A:A,C11) | L11: Да
A12: 11 | B12: Супы | C12: Харчо | D12: hot_kitchen | E12: =SUMIF(Техкарты!A:A,C12,Техкарты!D:D) | F12: =SUMIF(Техкарты!A:A,C12,Техкарты!G:G) | G12: 18 | H12: =IF(G12>0,F12/G12*100,0) | I12: =IF(F12>0,(G12-F12)/F12*100,0) | J12: =COUNTIF(Техкарты!A:A,C12) | L12: Да
A13: 12 | B13: Супы | C13: Чечивица | D13: hot_kitchen | E13: =SUMIF(Техкарты!A:A,C13,Техкарты!D:D) | F13: =SUMIF(Техкарты!A:A,C13,Техкарты!G:G) | G13: 12 | H13: =IF(G13>0,F13/G13*100,0) | I13: =IF(F13>0,(G13-F13)/F13*100,0) | J13: =COUNTIF(Техкарты!A:A,C13) | L13: Да
A14: 13 | B14: Супы | C14: Суп Хрущевский | D14: hot_kitchen | E14: =SUMIF(Техкарты!A:A,C14,Техкарты!D:D) | F14: =SUMIF(Техкарты!A:A,C14,Техкарты!G:G) | G14: 14 | H14: =IF(G14>0,F14/G14*100,0) | I14: =IF(F14>0,(G14-F14)/F14*100,0) | J14: =COUNTIF(Техкарты!A:A,C14) | L14: Да
A15: 14 | B15: Супы | C15: Тефттел Шурбо | D15: hot_kitchen | E15: =SUMIF(Техкарты!A:A,C15,Техкарты!D:D) | F15: =SUMIF(Техкарты!A:A,C15,Техкарты!G:G) | G15: 25 | H15: =IF(G15>0,F15/G15*100,0) | I15: =IF(F15>0,(G15-F15)/F15*100,0) | J15: =COUNTIF(Техкарты!A:A,C15) | L15: Да
A16: 15 | B16: Супы | C16: Забон Шурбо | D16: hot_kitchen | E16: =SUMIF(Техкарты!A:A,C16,Техкарты!D:D) | F16: =SUMIF(Техкарты!A:A,C16,Техкарты!G:G) | G16: 23 | H16: =IF(G16>0,F16/G16*100,0) | I16: =IF(F16>0,(G16-F16)/F16*100,0) | J16: =COUNTIF(Техкарты!A:A,C16) | L16: Да
A17: 16 | B17: Супы | C17: Илик Шурбо | D17: hot_kitchen | E17: =SUMIF(Техкарты!A:A,C17,Техкарты!D:D) | F17: =SUMIF(Техкарты!A:A,C17,Техкарты!G:G) | G17: 62 | H17: =IF(G17>0,F17/G17*100,0) | I17: =IF(F17>0,(G17-F17)/F17*100,0) | J17: =COUNTIF(Техкарты!A:A,C17) | L17: Да
A18: 17 | B18: Супы | C18: Дум Шурбо | D18: hot_kitchen | E18: =SUMIF(Техкарты!A:A,C18,Техкарты!D:D) | F18: =SUMIF(Техкарты!A:A,C18,Техкарты!G:G) | G18: 42 | H18: =IF(G18>0,F18/G18*100,0) | I18: =IF(F18>0,(G18-F18)/F18*100,0) | J18: =COUNTIF(Техкарты!A:A,C18) | L18: Да
A19: 18 | B19: Супы | C19: Бедона Шурбо | D19: hot_kitchen | E19: =SUMIF(Техкарты!A:A,C19,Техкарты!D:D) | F19: =SUMIF(Техкарты!A:A,C19,Техкарты!G:G) | G19: 41 | H19: =IF(G19>0,F19/G19*100,0) | I19: =IF(F19>0,(G19-F19)/F19*100,0) | J19: =COUNTIF(Техкарты!A:A,C19) | L19: Да
A20: 19 | B20: Супы | C20: Кавурга Шурбо | D20: hot_kitchen | E20: =SUMIF(Техкарты!A:A,C20,Техкарты!D:D) | F20: =SUMIF(Техкарты!A:A,C20,Техкарты!G:G) | G20: 47 | H20: =IF(G20>0,F20/G20*100,0) | I20: =IF(F20>0,(G20-F20)/F20*100,0) | J20: =COUNTIF(Техкарты!A:A,C20) | L20: Да
A21: 20 | B21: Вторые (готовые) | C21: Кавурдок | D21: hot_kitchen | E21: =SUMIF(Техкарты!A:A,C21,Техкарты!D:D) | F21: =SUMIF(Техкарты!A:A,C21,Техкарты!G:G) | H21: =IF(G21>0,F21/G21*100,0) | I21: =IF(F21>0,(G21-F21)/F21*100,0) | J21: =COUNTIF(Техкарты!A:A,C21) | L21: Да
A22: 21 | B22: Вторые (готовые) | C22: Жазза | D22: hot_kitchen | E22: =SUMIF(Техкарты!A:A,C22,Техкарты!D:D) | F22: =SUMIF(Техкарты!A:A,C22,Техкарты!G:G) | H22: =IF(G22>0,F22/G22*100,0) | I22: =IF(F22>0,(G22-F22)/F22*100,0) | J22: =COUNTIF(Техкарты!A:A,C22) | L22: Да
A23: 22 | B23: Вторые (готовые) | C23: Ребришки | D23: hot_kitchen | E23: =SUMIF(Техкарты!A:A,C23,Техкарты!D:D) | F23: =SUMIF(Техкарты!A:A,C23,Техкарты!G:G) | H23: =IF(G23>0,F23/G23*100,0) | I23: =IF(F23>0,(G23-F23)/F23*100,0) | J23: =COUNTIF(Техкарты!A:A,C23) | L23: Да
A24: 23 | B24: Вторые (готовые) | C24: Илик Кавур | D24: hot_kitchen | E24: =SUMIF(Техкарты!A:A,C24,Техкарты!D:D) | F24: =SUMIF(Техкарты!A:A,C24,Техкарты!G:G) | H24: =IF(G24>0,F24/G24*100,0) | I24: =IF(F24>0,(G24-F24)/F24*100,0) | J24: =COUNTIF(Техкарты!A:A,C24) | L24: Да
A25: 24 | B25: Вторые (готовые) | C25: Дум Кавур | D25: hot_kitchen | E25: =SUMIF(Техкарты!A:A,C25,Техкарты!D:D) | F25: =SUMIF(Техкарты!A:A,C25,Техкарты!G:G) | H25: =IF(G25>0,F25/G25*100,0) | I25: =IF(F25>0,(G25-F25)/F25*100,0) | J25: =COUNTIF(Техкарты!A:A,C25) | L25: Да
A26: 25 | B26: Вторые (готовые) | C26: Буйин Куй | D26: hot_kitchen | E26: =SUMIF(Техкарты!A:A,C26,Техкарты!D:D) | F26: =SUMIF(Техкарты!A:A,C26,Техкарты!G:G) | H26: =IF(G26>0,F26/G26*100,0) | I26: =IF(F26>0,(G26-F26)/F26*100,0) | J26: =COUNTIF(Техкарты!A:A,C26) | L26: Да
A27: 26 | B27: Вторые (готовые) | C27: Бедона Кавур | D27: hot_kitchen | E27: =SUMIF(Техкарты!A:A,C27,Техкарты!D:D) | F27: =SUMIF(Техкарты!A:A,C27,Техкарты!G:G) | H27: =IF(G27>0,F27/G27*100,0) | I27: =IF(F27>0,(G27-F27)/F27*100,0) | J27: =COUNTIF(Техкарты!A:A,C27) | L27: Да
A28: 27 | B28: Вторые (готовые) | C28: Казон Кавурдок | D28: hot_kitchen | E28: =SUMIF(Техкарты!A:A,C28,Техкарты!D:D) | F28: =SUMIF(Техкарты!A:A,C28,Техкарты!G:G) | H28: =IF(G28>0,F28/G28*100,0) | I28: =IF(F28>0,(G28-F28)/F28*100,0) | J28: =COUNTIF(Техкарты!A:A,C28) | L28: Да
A29: 28 | B29: Вторые (готовые) | C29: Казон Кабо Баранина | D29: hot_kitchen | E29: =SUMIF(Техкарты!A:A,C29,Техкарты!D:D) | F29: =SUMIF(Техкарты!A:A,C29,Техкарты!G:G) | H29: =IF(G29>0,F29/G29*100,0) | I29: =IF(F29>0,(G29-F29)/F29*100,0) | J29: =COUNTIF(Техкарты!A:A,C29) | L29: Да
A30: 29 | B30: Вторые (готовые) | C30: Котлет Сыром | D30: hot_kitchen | E30: =SUMIF(Техкарты!A:A,C30,Техкарты!D:D) | F30: =SUMIF(Техкарты!A:A,C30,Техкарты!G:G) | H30: =IF(G30>0,F30/G30*100,0) | I30: =IF(F30>0,(G30-F30)/F30*100,0) | J30: =COUNTIF(Техкарты!A:A,C30) | L30: Да
A31: 30 | B31: Вторые (готовые) | C31: Плов Ташкентский | D31: hot_kitchen | E31: =SUMIF(Техкарты!A:A,C31,Техкарты!D:D) | F31: =SUMIF(Техкарты!A:A,C31,Техкарты!G:G) | H31: =IF(G31>0,F31/G31*100,0) | I31: =IF(F31>0,(G31-F31)/F31*100,0) | J31: =COUNTIF(Техкарты!A:A,C31) | L31: Да
A32: 31 | B32: Вторые (готовые) | C32: Тбака | D32: hot_kitchen | E32: =SUMIF(Техкарты!A:A,C32,Техкарты!D:D) | F32: =SUMIF(Техкарты!A:A,C32,Техкарты!G:G) | H32: =IF(G32>0,F32/G32*100,0) | I32: =IF(F32>0,(G32-F32)/F32*100,0) | J32: =COUNTIF(Техкарты!A:A,C32) | L32: Да
... A34: 33 | B34: Гарниры | C34: Масса Порция | D34: hot_kitchen | E34: =SUMIF(Техкарты!A:A,C34,Техкарты!D:D) | F34: =SUMIF(Техкарты!A:A,C34,Техкарты!G:G) | H34: =IF(G34>0,F34/G34*100,0) | I34: =IF(F34>0,(G34-F34)/F34*100,0) | J34: =COUNTIF(Техкарты!A:A,C34) | L34: Да
A35: 34 | B35: Гарниры | C35: Масса *Кг | D35: hot_kitchen | E35: =SUMIF(Техкарты!A:A,C35,Техкарты!D:D) | F35: =SUMIF(Техкарты!A:A,C35,Техкарты!G:G) | G35: 6 | H35: =IF(G35>0,F35/G35*100,0) | I35: =IF(F35>0,(G35-F35)/F35*100,0) | J35: =COUNTIF(Техкарты!A:A,C35) | L35: Да
A36: 35 | B36: Гарниры | C36: Масса*Вых | D36: hot_kitchen | E36: =SUMIF(Техкарты!A:A,C36,Техкарты!D:D) | F36: =SUMIF(Техкарты!A:A,C36,Техкарты!G:G) | H36: =IF(G36>0,F36/G36*100,0) | I36: =IF(F36>0,(G36-F36)/F36*100,0) | J36: =COUNTIF(Техкарты!A:A,C36) | L36: Да
A37: 36 | B37: Завтраки | C37: Кулча | D37: hot_kitchen | E37: =SUMIF(Техкарты!A:A,C37,Техкарты!D:D) | F37: =SUMIF(Техкарты!A:A,C37,Техкарты!G:G) | H37: =IF(G37>0,F37/G37*100,0) | I37: =IF(F37>0,(G37-F37)/F37*100,0) | J37: =COUNTIF(Техкарты!A:A,C37) | L37: Да
A38: 37 | B38: Завтраки | C38: Блинчик | D38: hot_kitchen | E38: =SUMIF(Техкарты!A:A,C38,Техкарты!D:D) | F38: =SUMIF(Техкарты!A:A,C38,Техкарты!G:G) | H38: =IF(G38>0,F38/G38*100,0) | I38: =IF(F38>0,(G38-F38)/F38*100,0) | J38: =COUNTIF(Техкарты!A:A,C38) | L38: Да
A39: 38 | B39: Завтраки | C39: Блинчик С Творогом | D39: hot_kitchen | E39: =SUMIF(Техкарты!A:A,C39,Техкарты!D:D) | F39: =SUMIF(Техкарты!A:A,C39,Техкарты!G:G) | H39: =IF(G39>0,F39/G39*100,0) | I39: =IF(F39>0,(G39-F39)/F39*100,0) | J39: =COUNTIF(Техкарты!A:A,C39) | L39: Да
A40: 39 | B40: Завтраки | C40: Блинчик С Медом | D40: hot_kitchen | E40: =SUMIF(Техкарты!A:A,C40,Техкарты!D:D) | F40: =SUMIF(Техкарты!A:A,C40,Техкарты!G:G) | H40: =IF(G40>0,F40/G40*100,0) | I40: =IF(F40>0,(G40-F40)/F40*100,0) | J40: =COUNTIF(Техкарты!A:A,C40) | L40: Да
A41: 40 | B41: Завтраки | C41: Блинчик С Мясом | D41: hot_kitchen | E41: =SUMIF(Техкарты!A:A,C41,Техкарты!D:D) | F41: =SUMIF(Техкарты!A:A,C41,Техкарты!G:G) | H41: =IF(G41>0,F41/G41*100,0) | I41: =IF(F41>0,(G41-F41)/F41*100,0) | J41: =COUNTIF(Техкарты!A:A,C41) | L41: Да
...

Sheet Техкарты
A1: Блюдо | B1: Категория | C1: Ингредиент | D1: Масса (г) | E1: Ед. | F1: Цена за кг | G1: Стоимость
A2: Салат Каприз | B2: Салаты | C2: тил | D2: 40 | E2: г | F2: 125 | G2: 5
A3: Салат Каприз | C3: маенез | D3: 30 | E3: г | F3: 20.5 | G3: 0.61
A4: Салат Каприз | C4: грибы | D4: 10 | E4: г | F4: 96 | G4: 0.96
A5: Салат Каприз | C5: окорочка | D5: 40 | E5: г | F5: 80 | G5: 3.2
A6: Салат Каприз | C6: зеленый горошек | D6: 10 | E6: г | F6: 50 | G6: 0.5
A7: Салат Каприз | C7: салат лист | D7: 10 | E7: г | F7: 2 | G7: 0.02
A8: Салат Каприз | C8: черри | D8: 10 | E8: г | F8: 20 | G8: 0.2
C9: ИТОГО | F9: Цена: 22.0 | G9: 10.49
A11: Мастова | B11: Супы | C11: ег | D11: 200 | E11: г | F11: 17 | G11: 3.4
A12: Мастова | C12: пиез | D12: 200 | E12: г | F12: 10 | G12: 2
A13: Мастова | C13: мясо | D13: 500 | E13: г | F13: 130 | G13: 65
A14: Мастова | C14: сабзи | D14: 450 | E14: г | F14: 10 | G14: 4.5
A15: Мастова | C15: картошка | D15: 400 | E15: г | F15: 10 | G15: 4
A16: Мастова | C16: балгар | D16: 300 | E16: г | F16: 53.6 | G16: 16.08
A17: Мастова | C17: гурунч | D17: 450 | E17: г | F17: 15 | G17: 6.75
A18: Мастова | C18: кайла | D18: 15 | E18: г | F18: 100 | G18: 1.5
A19: Мастова | C19: специ | D19: 50 | E19: г | F19: 100 | G19: 5
A20: Мастова | C20: сув | D20: 5000 | E20: г | F20: 0.4 | G20: 2
A21: Мастова | C21: катик | D21: 1000 | E21: г | F21: 10 | G21: 10
A22: Мастова | C22: порция | D22: 250 | E22: г | F22: 0 | G22: 0
A23: Мастова | C23: вых | D23: 34260 | E23: г | F23: 0 | G23: 0
C24: ИТОГО | F24: Цена: 12.0 | G24: 120.23
A26: Реза Шурбо | B26: Супы | C26: ег | D26: 150 | E26: г | F26: 17 | G26: 2.55
A27: Реза Шурбо | C27: пиез | D27: 200 | E27: г | F27: 10 | G27: 2
A28: Реза Шурбо | C28: мясо | D28: 500 | E28: г | F28: 130 | G28: 65
A29: Реза Шурбо | C29: сабзи | D29: 600 | E29: г | F29: 10 | G29: 6
A30: Реза Шурбо | C30: картошка | D30: 1000 | E30: г | F30: 10 | G30: 10
A31: Реза Шурбо | C31: балгар | D31: 450 | E31: г | F31: 53.6 | G31: 24.12
A32: Реза Шурбо | C32: думба | D32: 150 | E32: г | F32: 100 | G32: 15
A33: Реза Шурбо | C33: нухот | D33: 300 | E33: г | F33: 10 | G33: 3
A34: Реза Шурбо | C34: специ | D34: 50 | E34: г | F34: 100 | G34: 5
A35: Реза Шурбо | C35: сув | D35: 5000 | E35: г | F35: 0.4 | G35: 2
A36: Реза Шурбо | C36: томат | D36: 390 | E36: г | F36: 25 | G36: 9.75
A37: Реза Шурбо | C37: селдерей | D37: 25 | E37: г | F37: 100 | G37: 2.5
A38: Реза Шурбо | C38: сметана | D38: 930 | E38: г | F38: 15 | G38: 13.95
... A40: Реза Шурбо | C40: вых | D40: 31435.5 | E40: г | F40: 0 | G40: 0
C41: ИТОГО | F41: Цена: 16.0 | G41: 160.87
A43: Лагман | B43: Супы | C43: ег | D43: 200 | E43: г | F43: 17 | G43: 3.4
A44: Лагман | C44: пиез | D44: 250 | E44: г | F44: 10 | G44: 2.5
...

Sheet Ингредиенты
A1: № | B1: Ингредиент | C1: Ед. | D1: Цена за ед. (TJS) | E1: Отходы % | F1: Мин. остаток | G1: Категория | H1: Используется в блюдах (шт.)
A2: 1 | B2: 0.2 | C2: кг | D2: 10 | E2: 0 | G2: Прочее | H2: 1
A3: 2 | B3: 0.5 | C3: кг | D3: 2 | E3: 0 | G3: Прочее | H3: 1
A4: 3 | B4: 1 | C4: кг | D4: 0.2 | E4: 0 | G4: Прочее | H4: 1
A5: 4 | B5: 3в1 | C5: кг | D5: 21 | E5: 0 | G5: Прочее | H5: 5
A6: 5 | B6: асал | C6: кг | D6: 45 | E6: 0 | G6: Прочее | H6: 2
A7: 6 | B7: балгар | C7: кг | D7: 53.6 | E7: 0 | G7: Овощи | H7: 12
A8: 7 | B8: балгар перец | C8: кг | D8: 53.6 | E8: 0 | G8: Овощи | H8: 1
A9: 8 | B9: балзам | C9: кг | D9: 230 | E9: 0 | G9: Прочее | H9: 4
A10: 9 | B10: балзамик | C10: кг | D10: 230 | E10: 0 | G10: Прочее | H10: 1
A11: 10 | B11: банан | C11: кг | D11: 25 | E11: 0 | G11: Прочее | H11: 1
A12: 11 | B12: бар ребро | C12: кг | D12: 300 | E12: 0 | G12: Мясо | H12: 2
A13: 12 | B13: баранина ребро | C13: кг | D13: 105 | E13: 0 | G13: Мясо | H13: 2
... A137: 136 | B137: шаурма | C137: кг | D137: 39 | E137: 0 | G137: Прочее | H137: 1

Sheet Инструкция
A1: RestOS — Шаблон импорта техкарт
A2: Ресторан: Шаршара-М
A4: ═══════════════════════════════════════════════════════
A5: ЛИСТ 1: "Блюда" — Список всех блюд меню
A6: ═══════════════════════════════════════════════════════
A8: Колонки:
A9: № — порядковый номер
A10: Категория — раздел меню (Салаты, Супы, Вторые...)
A11: Название — название блюда
A12: Станция — куда пойдёт марка при заказе:
A13: hot_kitchen = Горячий цех
A14: cold_kitchen = Холодный цех
... A71: 5. Загрузите файл в RestOS → Настройки → Импорт
